Workbook

Sheet Léeme
A1: Fed-ISIC2019 — resultados, semilla 42
A3: Métrica de todas las tablas: balanced accuracy (métrica oficial de FLamby para Fed-ISIC2019), en el test de cada centro y en el test agrupado (Pooled test).
A4: Fuente: CSV de results_isic2019/seed42/ (rama fedisic2019-reports-docker, repo Ayax911/FLamby). Corridas en RTX 6000 Ada vía scripts/run_isic2019_docker.sh.
A6: Hojas
A7: Benchmark — 15 experimentos: Pooled, 6 locales y 8 estrategias con los hiperparámetros de flamby/config_isic2019.json (results_isic2019.csv).
A8: Malla — 233 combinaciones federadas con la malla del paper (Apéndice H): lr cliente 10^{-3..-0.5}, slr 10^{-3..-0.5} + 1 + 10, mu {0.001, 0.01, 0.1, 1} (results_isic2019_grid.csv). 201 completas; las 32 que divergieron (NaN: FedAdam/FedYogi con slr 1 y 10, FedAdagrad/Scaffold con slr 10, y una FedAdam con slr 0.316) aparecen en rojo, sin métricas. 155 corridas originales + 78 de la extensión del paper; se omitieron FedAvgFineTuning con lr 0.316 y repetir los 10 slr=1.0 ya divergidos.
A9: Malla mejor — la mejor corrida de la malla por estrategia vs la config del paper (fórmulas sobre la hoja Malla).
A10: Best config — las 8 estrategias de config_isic2019.json corridas de nuevo como seed42_best_* (results_isic2019_best.csv).
A11: Benchmark rerun — 7 estrategias que se entrenaron una segunda vez por un lanzamiento duplicado (results_isic2019_benchmark_rerun.csv).
A12: Repeticiones — misma config y semilla corrida 2–3 veces: ruido real de una corrida (fórmulas).
A13: FLamby paper — nuestras cifras vs las 5 semillas publicadas por FLamby (flamby/results/results_benchmark_fed_isic2019/isic_seed42..46.csv).
A14: Métricas detalladas — accuracy, AUC, F1, precisión, sensibilidad, especificidad y loss en el test agrupado, leídas de runs*/…/test/metrics.json.
... A21: 5. Celdas en negrita de 'Media 6 centros' y las columnas de comparación son fórmulas; las demás cifras son resultados copiados de los CSV.

Sheet Benchmark
A1: Estrategia / Método | B1: lr cliente | C1: lr servidor (slr) | D1: mu (FedProx) | E1: pasos fine-tuning | F1: Pooled test | G1: BCN | H1: HAM_vidir_molemax | I1: HAM_vidir_modern | J1: HAM_rosendahl | K1: MSK | L1: HAM_vienna_dias | M1: Media 6 centros
A2: Pooled Training | B2: 0.0005 | F2: 0.74981289 | G2: 0.74890687 | H2: 0.68801192 | I2: 0.67541929 | J2: 0.67144262 | K2: 0.70171099 | L2: 0.65690691 | M2: =IF(COUNT(G2:L2)=6,AVERAGE(G2:L2),"") -> 0.69039977
A3: Local 0 | B3: 0.0005 | F3: 0.65823531 | G3: 0.77680113 | H3: 0.46139631 | I3: 0.62310579 | J3: 0.35084033 | K3: 0.35827664 | L3: 0.65484234 | M3: =IF(COUNT(G3:L3)=6,AVERAGE(G3:L3),"") -> 0.53754376
A4: Local 1 | B4: 0.0005 | F4: 0.27797721 | G4: 0.20243323 | H4: 0.7713036 | I4: 0.39361124 | J4: 0.18372218 | K4: 0.35786436 | L4: 0.20345345 | M4: =IF(COUNT(G4:L4)=6,AVERAGE(G4:L4),"") -> 0.35206467
A5: Local 2 | B5: 0.0005 | F5: 0.44946632 | G5: 0.37421563 | H5: 0.69490483 | I5: 0.69725483 | J5: 0.39172316 | K5: 0.34817563 | L5: 0.66910661 | M5: =IF(COUNT(G5:L5)=6,AVERAGE(G5:L5),"") -> 0.52923011
A6: Local 3 | B6: 0.0005 | F6: 0.35036771 | G6: 0.27150557 | H6: 0.43984811 | I6: 0.51637438 | J6: 0.70912656 | K6: 0.44104308 | L6: 0.37237237 | M6: =IF(COUNT(G6:L6)=6,AVERAGE(G6:L6),"") -> 0.45837834
A7: Local 4 | B7: 0.0005 | F7: 0.19042508 | G7: 0.19394249 | H7: 0.35429725 | I7: 0.23309957 | J7: 0.21907854 | K7: 0.58524016 | L7: 0.38288288 | M7: =IF(COUNT(G7:L7)=6,AVERAGE(G7:L7),"") -> 0.32809015
A8: Local 5 | B8: 0.0005 | F8: 0.14133758 | G8: 0.14996005 | H8: 0.22927322 | I8: 0.15692148 | J8: 0.15409053 | K8: 0.34364049 | L8: 0.36467718 | M8: =IF(COUNT(G8:L8)=6,AVERAGE(G8:L8),"") -> 0.23309382
A9: FedAvg | B9: 0.01 | F9: 0.57804038 | G9: 0.60453684 | H9: 0.68074409 | I9: 0.57227822 | J9: 0.44648484 | K9: 0.47835498 | L9: 0.73423423 | M9: =IF(COUNT(G9:L9)=6,AVERAGE(G9:L9),"") -> 0.58610553
A10: FedProx | B10: 0.01 | D10: 0.001 | F10: 0.58924231 | G10: 0.62020452 | H10: 0.73318593 | I10: 0.56368271 | J10: 0.46054015 | K10: 0.48165327 | L10: 0.77627628 | M10: =IF(COUNT(G10:L10)=6,AVERAGE(G10:L10),"") -> 0.60592381
A11: FedAdam | B11: 0.01 | C11: 0.0031622777 | F11: 0.58995982 | G11: 0.58597159 | H11: 0.63467602 | I11: 0.74401498 | J11: 0.53712422 | K11: 0.40723562 | L11: 0.75187688 | M11: =IF(COUNT(G11:L11)=6,AVERAGE(G11:L11),"") -> 0.61014989
A12: FedYogi | B12: 0.01 | C12: 0.0031622777 | F12: 0.56305463 | G12: 0.57977353 | H12: 0.68589694 | I12: 0.75236186 | J12: 0.42361775 | K12: 0.43578644 | L12: 0.77027027 | M12: =IF(COUNT(G12:L12)=6,AVERAGE(G12:L12),"") -> 0.60795113
A13: FedAdagrad | B13: 0.01 | C13: 0.031622777 | F13: 0.54461635 | G13: 0.56031309 | H13: 0.56026726 | I13: 0.71252646 | J13: 0.41526266 | K13: 0.42393321 | L13: 0.72484985 | M13: =IF(COUNT(G13:L13)=6,AVERAGE(G13:L13),"") -> 0.56619209
A14: Scaffold | B14: 0.01 | C14: 1 | F14: 0.61572087 | G14: 0.65818393 | H14: 0.67249567 | I14: 0.59433968 | J14: 0.4741938 | K14: 0.35168007 | L14: 0.62331081 | M14: =IF(COUNT(G14:L14)=6,AVERAGE(G14:L14),"") -> 0.56236733
A15: Cyclic | B15: 0.0031622777 | F15: 0.48350349 | G15: 0.50021401 | H15: 0.54232306 | I15: 0.44500406 | J15: 0.44000758 | K15: 0.32075861 | L15: 0.62837838 | M15: =IF(COUNT(G15:L15)=6,AVERAGE(G15:L15),"") -> 0.47944762
A16: FedAvgFineTuning | B16: 0.01 | E16: 3 | F16: 0.61392588 | G16: 0.66731037 | H16: 0.66109402 | I16: 0.72435269 | J16: 0.44458799 | K16: 0.37693259 | L16: 0.64283033 | M16: =IF(COUNT(G16:L16)=6,AVERAGE(G16:L16),"") -> 0.58618467

Sheet Malla
A1: Estrategia / Método | B1: lr cliente | C1: lr servidor (slr) | D1: mu (FedProx) | E1: pasos fine-tuning | F1: Pooled test | G1: BCN | H1: HAM_vidir_molemax | I1: HAM_vidir_modern | J1: HAM_rosendahl | K1: MSK | L1: HAM_vienna_dias | M1: Media 6 centros | N1: Estado | O1: Rango en su estrategia | P1: Clave
A2: FedAvg | B2: 0.001 | F2: 0.51332405 | G2: 0.50935962 | H2: 0.63537781 | I2: 0.53651483 | J2: 0.4496011 | K2: 0.42918986 | L2: 0.60135135 | M2: =IF(COUNT(G2:L2)=6,AVERAGE(G2:L2),"") -> 0.5268991 | N2: ok | O2: =IF(F2="","",COUNTIFS($A$2:$A$234,A2,$F$2:$F$234,">"&F2)+1) -> 4 | P2: =A2&"|"&O2 -> FedAvg|4
A3: FedAvg | B3: 0.0031622777 | F3: 0.58331566 | G3: 0.59722167 | H3: 0.7181119 | I3: 0.70086357 | J3: 0.50943432 | K3: 0.42918986 | L3: 0.70101351 | M3: =IF(COUNT(G3:L3)=6,AVERAGE(G3:L3),"") -> 0.60930581 | N3: ok | O3: =IF(F3="","",COUNTIFS($A$2:$A$234,A3,$F$2:$F$234,">"&F3)+1) -> 2 | P3: =A3&"|"&O3 -> FedAvg|2
A4: FedAvg | B4: 0.01 | F4: 0.59098457 | G4: 0.62935183 | H4: 0.67966737 | I4: 0.6868192 | J4: 0.46987821 | K4: 0.4033189 | L4: 0.66478979 | M4: =IF(COUNT(G4:L4)=6,AVERAGE(G4:L4),"") -> 0.58897088 | N4: ok | O4: =IF(F4="","",COUNTIFS($A$2:$A$234,A4,$F$2:$F$234,">"&F4)+1) -> 1 | P4: =A4&"|"&O4 -> FedAvg|1
A5: FedAvg | B5: 0.031622777 | F5: 0.57499028 | G5: 0.60791927 | H5: 0.61156508 | I5: 0.71175813 | J5: 0.50088057 | K5: 0.35673057 | L5: 0.64883634 | M5: =IF(COUNT(G5:L5)=6,AVERAGE(G5:L5),"") -> 0.57294833 | N5: ok | O5: =IF(F5="","",COUNTIFS($A$2:$A$234,A5,$F$2:$F$234,">"&F5)+1) -> 3 | P5: =A5&"|"&O5 -> FedAvg|3
A6: FedAvg | B6: 0.1 | F6: 0.2474994 | G6: 0.22063056 | H6: 0.53717768 | I6: 0.27177719 | J6: 0.29230945 | K6: 0.45217481 | L6: 0.2957958 | M6: =IF(COUNT(G6:L6)=6,AVERAGE(G6:L6),"") -> 0.34497758 | N6: ok | O6: =IF(F6="","",COUNTIFS($A$2:$A$234,A6,$F$2:$F$234,">"&F6)+1) -> 5 | P6: =A6&"|"&O6 -> FedAvg|5
A7: FedAvg | B7: 0.31622777 | F7: 0.2285311 | G7: 0.22828283 | H7: 0.40729667 | I7: 0.27002482 | J7: 0.26221398 | K7: 0.1299732 | L7: 0.31006006 | M7: =IF(COUNT(G7:L7)=6,AVERAGE(G7:L7),"") -> 0.26797526 | N7: ok | O7: =IF(F7="","",COUNTIFS($A$2:$A$234,A7,$F$2:$F$234,">"&F7)+1) -> 6 | P7: =A7&"|"&O7 -> FedAvg|6
A8: FedProx | B8: 0.001 | D8: 0.001 | F8: 0.51375008 | G8: 0.51225304 | H8: 0.61717939 | I8: 0.52200919 | J8: 0.46822895 | K8: 0.42743764 | L8: 0.57695195 | M8: =IF(COUNT(G8:L8)=6,AVERAGE(G8:L8),"") -> 0.52067669 | N8: ok | O8: =IF(F8="","",COUNTIFS($A$2:$A$234,A8,$F$2:$F$234,">"&F8)+1) -> 11 | P8: =A8&"|"&O8 -> FedProx|11
A9: FedProx | B9: 0.001 | D9: 0.01 | F9: 0.50979786 | G9: 0.50104586 | H9: 0.63457027 | I9: 0.5311352 | J9: 0.47765999 | K9: 0.4004329 | L9: 0.57357357 | M9: =IF(COUNT(G9:L9)=6,AVERAGE(G9:L9),"") -> 0.5197363 | N9: ok | O9: =IF(F9="","",COUNTIFS($A$2:$A$234,A9,$F$2:$F$234,">"&F9)+1) -> 13 | P9: =A9&"|"&O9 -> FedProx|13
A10: FedProx | B10: 0.001 | D10: 0.1 | F10: 0.5131677 | G10: 0.50973094 | H10: 0.62715824 | I10: 0.53599429 | J10: 0.46043674 | K10: 0.43094207 | L10: 0.54917417 | M10: =IF(COUNT(G10:L10)=6,AVERAGE(G10:L10),"") -> 0.51890608 | N10: ok | O10: =IF(F10="","",COUNTIFS($A$2:$A$234,A10,$F$2:$F$234,">"&F10)+1) -> 12 | P10: =A10&"|"&O10 -> FedProx|12
A11: FedProx | B11: 0.001 | D11: 1 | F11: 0.50790298 | G11: 0.49755584 | H11: 0.63403192 | I11: 0.5326233 | J11: 0.47076937 | K11: 0.42084106 | L11: 0.5457958 | M11: =IF(COUNT(G11:L11)=6,AVERAGE(G11:L11),"") -> 0.51693621 | N11: ok | O11: =IF(F11="","",COUNTIFS($A$2:$A$234,A11,$F$2:$F$234,">"&F11)+1) -> 14 | P11: =A11&"|"&O11 -> FedProx|14
A12: FedProx | B12: 0.0031622777 | D12: 0.001 | F12: 0.57338443 | G12: 0.60257037 | H12: 0.66312248 | I12: 0.69279604 | J12: 0.50278114 | K12: 0.43248815 | L12: 0.65296547 | M12: =IF(COUNT(G12:L12)=6,AVERAGE(G12:L12),"") -> 0.59112061 | N12: ok | O12: =IF(F12="","",COUNTIFS($A$2:$A$234,A12,$F$2:$F$234,">"&F12)+1) -> 8 | P12: =A12&"|"&O12 -> FedProx|8
A13: FedProx | B13: 0.0031622777 | D13: 0.01 | F13: 0.58361751 | G13: 0.59232363 | H13: 0.65867141 | I13: 0.70985856 | J13: 0.54486142 | K13: 0.42063492 | L13: 0.6631006 | M13: =IF(COUNT(G13:L13)=6,AVERAGE(G13:L13),"") -> 0.59824176 | N13: ok | O13: =IF(F13="","",COUNTIFS($A$2:$A$234,A13,$F$2:$F$234,">"&F13)+1) -> 5 | P13: =A13&"|"&O13 -> FedProx|5
A14: FedProx | B14: 0.0031622777 | D14: 0.1 | F14: 0.56946188 | G14: 0.58379648 | H14: 0.72161123 | I14: 0.55365683 | J14: 0.4903956 | K14: 0.42238714 | L14: 0.6631006 | M14: =IF(COUNT(G14:L14)=6,AVERAGE(G14:L14),"") -> 0.57249131 | N14: ok | O14: =IF(F14="","",COUNTIFS($A$2:$A$234,A14,$F$2:$F$234,">"&F14)+1) -> 9 | P14: =A14&"|"&O14 -> FedProx|9
A15: FedProx | B15: 0.0031622777 | D15: 1 | F15: 0.57677969 | G15: 0.58659662 | H15: 0.65894059 | I15: 0.6947472 | J15: 0.54030304 | K15: 0.42568543 | L15: 0.60397898 | M15: =IF(COUNT(G15:L15)=6,AVERAGE(G15:L15),"") -> 0.58504198 | N15: ok | O15: =IF(F15="","",COUNTIFS($A$2:$A$234,A15,$F$2:$F$234,">"&F15)+1) -> 7 | P15: =A15&"|"&O15 -> FedProx|7
A16: FedProx | B16: 0.01 | D16: 0.001 | F16: 0.60470562 | G16: 0.65195266 | H16: 0.70906556 | I16: 0.72005369 | J16: 0.45334114 | K16: 0.40682334 | L16: 0.76276276 | M16: =IF(COUNT(G16:L16)=6,AVERAGE(G16:L16),"") -> 0.61733319 | N16: ok | O16: =IF(F16="","",COUNTIFS($A$2:$A$234,A16,$F$2:$F$234,">"&F16)+1) -> 2 | P16: =A16&"|"&O16 -> FedProx|2
A17: FedProx | B17: 0.01 | D17: 0.01 | F17: 0.61818087 | G17: 0.64388298 | H17: 0.69610652 | I17: 0.74871357 | J17: 0.51693385 | K17: 0.3982684 | L17: 0.70026276 | M17: =IF(COUNT(G17:L17)=6,AVERAGE(G17:L17),"") -> 0.61736135 | N17: ok | O17: =IF(F17="","",COUNTIFS($A$2:$A$234,A17,$F$2:$F$234,">"&F17)+1) -> 1 | P17: =A17&"|"&O17 -> FedProx|1
A18: FedProx | B18: 0.01 | D18: 0.1 | F18: 0.59971156 | G18: 0.6318568 | H18: 0.71821765 | I18: 0.58976582 | J18: 0.46643788 | K18: 0.43403422 | L18: 0.75600601 | M18: =IF(COUNT(G18:L18)=6,AVERAGE(G18:L18),"") -> 0.5993864 | N18: ok | O18: =IF(F18="","",COUNTIFS($A$2:$A$234,A18,$F$2:$F$234,">"&F18)+1) -> 3 | P18: =A18&"|"&O18 -> FedProx|3
A19: FedProx | B19: 0.01 | D19: 1 | F19: 0.58130982 | G19: 0.61217486 | H19: 0.65057681 | I19: 0.51985947 | J19: 0.47286654 | K19: 0.41713049 | L19: 0.68674925 | M19: =IF(COUNT(G19:L19)=6,AVERAGE(G19:L19),"") -> 0.5598929 | N19: ok | O19: =IF(F19="","",COUNTIFS($A$2:$A$234,A19,$F$2:$F$234,">"&F19)+1) -> 6 | P19: =A19&"|"&O19 -> FedProx|6
... A31: FedProx | B31: 0.31622777 | D31: 1 | F31: 0.14351673 | G31: 0.13604506 | H31: 0.21352624 | I31: 0.17380496 | J31: 0.18831169 | K31: 0.37621109 | L31: 0.2972973 | M31: =IF(COUNT(G31:L31)=6,AVERAGE(G31:L31),"") -> 0.23086606 | N31: ok | O31: =IF(F31="","",COUNTIFS($A$2:$A$234,A31,$F$2:$F$234,">"&F31)+1) -> 23 | P31: =A31&"|"&O31 -> FedProx|23
A32: FedAdam | B32: 0.001 | C32: 0.001 | F32: 0.41693346 | G32: 0.38865657 | H32: 0.60171121 | I32: 0.46220114 | J32: 0.39572474 | K32: 0.38857967 | L32: 0.70964715 | M32: =IF(COUNT(G32:L32)=6,AVERAGE(G32:L32),"") -> 0.49108675 | N32: ok | O32: =IF(F32="","",COUNTIFS($A$2:$A$234,A32,$F$2:$F$234,">"&F32)+1) -> 11 | P32: =A32&"|"&O32 -> FedAdam|11
A33: FedAdam | B33: 0.001 | C33: 0.0031622777 | F33: 0.47883175 | G33: 0.47573137 | H33: 0.55912325 | I33: 0.63832498 | J33: 0.46090076 | K33: 0.37827252 | L33: 0.61824324 | M33: =IF(COUNT(G33:L33)=6,AVERAGE(G33:L33),"") -> 0.52176602 | N33: ok | O33: =IF(F33="","",COUNTIFS($A$2:$A$234,A33,$F$2:$F$234,">"&F33)+1) -> 7 | P33: =A33&"|"&O33 -> FedAdam|7
A34: FedAdam | B34: 0.001 | C34: 0.01 | F34: 0.49975118 | G34: 0.52222021 | H34: 0.63898289 | I34: 0.62517049 | J34: 0.35125925 | K34: 0.34446506 | L34: 0.56137387 | M34: =IF(COUNT(G34:L34)=6,AVERAGE(G34:L34),"") -> 0.5072453 | N34: ok | O34: =IF(F34="","",COUNTIFS($A$2:$A$234,A34,$F$2:$F$234,">"&F34)+1) -> 5 | P34: =A34&"|"&O34 -> FedAdam|5
A35: FedAdam | B35: 0.001 | C35: 0.031622777 | F35: 0.45586138 | G35: 0.44250718 | H35: 0.46547779 | I35: 0.51225875 | J35: 0.39016351 | K35: 0.44341373 | L35: 0.753003 | M35: =IF(COUNT(G35:L35)=6,AVERAGE(G35:L35),"") -> 0.50113733 | N35: ok | O35: =IF(F35="","",COUNTIFS($A$2:$A$234,A35,$F$2:$F$234,">"&F35)+1) -> 8 | P35: =A35&"|"&O35 -> FedAdam|8
A36: FedAdam | B36: 0.001 | C36: 0.1 | F36: 0.125 | G36: 0.125 | H36: 0.2 | I36: 0.14285714 | J36: 0.14285714 | K36: 0.33333333 | L36: 0.25 | M36: =IF(COUNT(G36:L36)=6,AVERAGE(G36:L36),"") -> 0.19900794 | N36: ok | O36: =IF(F36="","",COUNTIFS($A$2:$A$234,A36,$F$2:$F$234,">"&F36)+1) -> 19 | P36: =A36&"|"&O36 -> FedAdam|19
A37: FedAdam | B37: 0.001 | C37: 0.31622777 | F37: 0.125 | G37: 0.125 | H37: 0.2 | I37: 0.14285714 | J37: 0.14285714 | K37: 0.33333333 | L37: 0.25 | M37: =IF(COUNT(G37:L37)=6,AVERAGE(G37:L37),"") -> 0.19900794 | N37: ok | O37: =IF(F37="","",COUNTIFS($A$2:$A$234,A37,$F$2:$F$234,">"&F37)+1) -> 19 | P37: =A37&"|"&O37 -> FedAdam|19
A38: FedAdam | B38: 0.001 | C38: 1 | M38: =IF(COUNT(G38:L38)=6,AVERAGE(G38:L38),"") | N38: divergió (NaN) | O38: =IF(F38="","",COUNTIFS($A$2:$A$234,A38,$F$2:$F$234,">"&F38)+1) | P38: =A38&"|"&O38 -> FedAdam|
A39: FedAdam | B39: 0.001 | C39: 10 | M39: =IF(COUNT(G39:L39)=6,AVERAGE(G39:L39),"") | N39: divergió (NaN) | O39: =IF(F39="","",COUNTIFS($A$2:$A$234,A39,$F$2:$F$234,">"&F39)+1) | P39: =A39&"|"&O39 -> FedAdam|
A40: FedAdam | B40: 0.0031622777 | C40: 0.001 | F40: 0.4495364 | G40: 0.4563255 | H40: 0.60860411 | I40: 0.49976078 | J40: 0.38297723 | K40: 0.32426304 | L40: 0.69087838 | M40: =IF(COUNT(G40:L40)=6,AVERAGE(G40:L40),"") -> 0.49380151 | N40: ok | O40: =IF(F40="","",COUNTIFS($A$2:$A$234,A40,$F$2:$F$234,">"&F40)+1) -> 9 | P40: =A40&"|"&O40 -> FedAdam|9
A41: FedAdam | B41: 0.0031622777 | C41: 0.0031622777 | F41: 0.56221136 | G41: 0.56596062 | H41: 0.69844261 | I41: 0.67783368 | J41: 0.52401292 | K41: 0.35106164 | L41: 0.56456456 | M41: =IF(COUNT(G41:L41)=6,AVERAGE(G41:L41),"") -> 0.563646 | N41: ok | O41: =IF(F41="","",COUNTIFS($A$2:$A$234,A41,$F$2:$F$234,">"&F41)+1) -> 2 | P41: =A41&"|"&O41 -> FedAdam|2
A42: FedAdam | B42: 0.0031622777 | C42: 0.01 | F42: 0.48235716 | G42: 0.50557078 | H42: 0.56393001 | I42: 0.48503525 | J42: 0.35933762 | K42: 0.4612451 | L42: 0.64395646 | M42: =IF(COUNT(G42:L42)=6,AVERAGE(G42:L42),"") -> 0.5031792 | N42: ok | O42: =IF(F42="","",COUNTIFS($A$2:$A$234,A42,$F$2:$F$234,">"&F42)+1) -> 6 | P42: =A42&"|"&O42 -> FedAdam|6
A43: FedAdam | B43: 0.0031622777 | C43: 0.031622777 | F43: 0.39904126 | G43: 0.39662026 | H43: 0.5399154 | I43: 0.49369454 | J43: 0.30278505 | K43: 0.41207998 | L43: 0.64114114 | M43: =IF(COUNT(G43:L43)=6,AVERAGE(G43:L43),"") -> 0.46437273 | N43: ok | O43: =IF(F43="","",COUNTIFS($A$2:$A$234,A43,$F$2:$F$234,">"&F43)+1) -> 12 | P43: =A43&"|"&O43 -> FedAdam|12
A44: FedAdam | B44: 0.0031622777 | C44: 0.1 | F44: 0.13255311 | G44: 0.12651393 | H44: 0.092857143 | I44: 0.098214286 | J44: 0.17176871 | K44: 0.26530612 | L44: 0.25 | M44: =IF(COUNT(G44:L44)=6,AVERAGE(G44:L44),"") -> 0.16744336 | N44: ok | O44: =IF(F44="","",COUNTIFS($A$2:$A$234,A44,$F$2:$F$234,">"&F44)+1) -> 17 | P44: =A44&"|"&O44 -> FedAdam|17
A45: FedAdam | B45: 0.0031622777 | C45: 0.31622777 | F45: 0.125 | G45: 0.125 | H45: 0.2 | I45: 0.14285714 | J45: 0.14285714 | K45: 0 | L45: 0 | M45: =IF(COUNT(G45:L45)=6,AVERAGE(G45:L45),"") -> 0.10178571 | N45: ok | O45: =IF(F45="","",COUNTIFS($A$2:$A$234,A45,$F$2:$F$234,">"&F45)+1) -> 19 | P45: =A45&"|"&O45 -> FedAdam|19
A46: FedAdam | B46: 0.0031622777 | C46: 1 | M46: =IF(COUNT(G46:L46)=6,AVERAGE(G46:L46),"") | N46: divergió (NaN) | O46: =IF(F46="","",COUNTIFS($A$2:$A$234,A46,$F$2:$F$234,">"&F46)+1) | P46: =A46&"|"&O46 -> FedAdam|
A47: FedAdam | B47: 0.0031622777 | C47: 10 | M47: =IF(COUNT(G47:L47)=6,AVERAGE(G47:L47),"") | N47: divergió (NaN) | O47: =IF(F47="","",COUNTIFS($A$2:$A$234,A47,$F$2:$F$234,">"&F47)+1) | P47: =A47&"|"&O47 -> FedAdam|
A48: FedAdam | B48: 0.01 | C48: 0.001 | F48: 0.52536867 | G48: 0.56205239 | H48: 0.57802346 | I48: 0.51823236 | J48: 0.44766111 | K48: 0.38332303 | L48: 0.67924174 | M48: =IF(COUNT(G48:L48)=6,AVERAGE(G48:L48),"") -> 0.52808901 | N48: ok | O48: =IF(F48="","",COUNTIFS($A$2:$A$234,A48,$F$2:$F$234,">"&F48)+1) -> 3 | P48: =A48&"|"&O48 -> FedAdam|3
A49: FedAdam | B49: 0.01 | C49: 0.0031622777 | F49: 0.58594798 | G49: 0.61002884 | H49: 0.68790617 | I49: 0.68349623 | J49: 0.51324396 | K49: 0.39167182 | L49: 0.60867117 | M49: =IF(COUNT(G49:L49)=6,AVERAGE(G49:L49),"") -> 0.58250303 | N49: ok | O49: =IF(F49="","",COUNTIFS($A$2:$A$234,A49,$F$2:$F$234,">"&F49)+1) -> 1 | P49: =A49&"|"&O49 -> FedAdam|1
A50: FedAdam | B50: 0.01 | C50: 0.01 | F50: 0.52180659 | G50: 0.56896687 | H50: 0.62744664 | I50: 0.64082661 | J50: 0.34321501 | K50: 0.39167182 | L50: 0.70364114 | M50: =IF(COUNT(G50:L50)=6,AVERAGE(G50:L50),"") -> 0.54596135 | N50: ok | O50: =IF(F50="","",COUNTIFS($A$2:$A$234,A50,$F$2:$F$234,">"&F50)+1) -> 4 | P50: =A50&"|"&O50 -> FedAdam|4
A51: FedAdam | B51: 0.01 | C51: 0.031622777 | F51: 0.17693009 | G51: 0.19058805 | H51: 0.21048409 | I51: 0.21936065 | J51: 0.16363679 | K51: 0.28396207 | L51: 0.25 | M51: =IF(COUNT(G51:L51)=6,AVERAGE(G51:L51),"") -> 0.21967194 | N51: ok | O51: =IF(F51="","",COUNTIFS($A$2:$A$234,A51,$F$2:$F$234,">"&F51)+1) -> 15 | P51: =A51&"|"&O51 -> FedAdam|15
...

Sheet Malla mejor
A1: Estrategia | B1: Corridas válidas | C1: Mejor Pooled (malla) | D1: lr | E1: slr | F1: mu | G1: Pooled con config del paper | H1: Mejor − paper | I1: Pooled peor (malla)
A2: FedAvg | B2: =COUNTIFS(Malla!$A$2:$A$234,A2,Malla!$N$2:$N$234,"ok") -> 6 | C2: =_xlfn.MAXIFS(Malla!$F$2:$F$234,Malla!$A$2:$A$234,A2) -> 0.59098457 | D2: =INDEX(Malla!$B$2:$B$234,MATCH($A2&"|1",Malla!$P$2:$P$234,0)) -> 0.01 | E2: =IF(INDEX(Malla!$C$2:$C$234,MATCH($A2&"|1",Malla!$P$2:$P$234,0))="","",INDEX(Malla!$C$2:$C$234,MATCH($A2&"|1",Malla!$P$2:$P$234,0))) | F2: =IF(INDEX(Malla!$D$2:$D$234,MATCH($A2&"|1",Malla!$P$2:$P$234,0))="","",INDEX(Malla!$D$2:$D$234,MATCH($A2&"|1",Malla!$P$2:$P$234,0))) | G2: =INDEX(Benchmark!$F$2:$F$16,MATCH(A2,Benchmark!$A$2:$A$16,0)) -> 0.57804038 | H2: =C2-G2 -> 0.012944187 | I2: =_xlfn.MINIFS(Malla!$F$2:$F$234,Malla!$A$2:$A$234,A2) -> 0.2285311
A3: FedProx | B3: =COUNTIFS(Malla!$A$2:$A$234,A3,Malla!$N$2:$N$234,"ok") -> 24 | C3: =_xlfn.MAXIFS(Malla!$F$2:$F$234,Malla!$A$2:$A$234,A3) -> 0.61818087 | D3: =INDEX(Malla!$B$2:$B$234,MATCH($A3&"|1",Malla!$P$2:$P$234,0)) -> 0.01 | E3: =IF(INDEX(Malla!$C$2:$C$234,MATCH($A3&"|1",Malla!$P$2:$P$234,0))="","",INDEX(Malla!$C$2:$C$234,MATCH($A3&"|1",Malla!$P$2:$P$234,0))) | F3: =IF(INDEX(Malla!$D$2:$D$234,MATCH($A3&"|1",Malla!$P$2:$P$234,0))="","",INDEX(Malla!$D$2:$D$234,MATCH($A3&"|1",Malla!$P$2:$P$234,0))) -> 0.01 | G3: =INDEX(Benchmark!$F$2:$F$16,MATCH(A3,Benchmark!$A$2:$A$16,0)) -> 0.58924231 | H3: =C3-G3 -> 0.028938564 | I3: =_xlfn.MINIFS(Malla!$F$2:$F$234,Malla!$A$2:$A$234,A3) -> 0.1300103
A4: FedAdam | B4: =COUNTIFS(Malla!$A$2:$A$234,A4,Malla!$N$2:$N$234,"ok") -> 35 | C4: =_xlfn.MAXIFS(Malla!$F$2:$F$234,Malla!$A$2:$A$234,A4) -> 0.58594798 | D4: =INDEX(Malla!$B$2:$B$234,MATCH($A4&"|1",Malla!$P$2:$P$234,0)) -> 0.01 | E4: =IF(INDEX(Malla!$C$2:$C$234,MATCH($A4&"|1",Malla!$P$2:$P$234,0))="","",INDEX(Malla!$C$2:$C$234,MATCH($A4&"|1",Malla!$P$2:$P$234,0))) -> 0.0031622777 | F4: =IF(INDEX(Malla!$D$2:$D$234,MATCH($A4&"|1",Malla!$P$2:$P$234,0))="","",INDEX(Malla!$D$2:$D$234,MATCH($A4&"|1",Malla!$P$2:$P$234,0))) | G4: =INDEX(Benchmark!$F$2:$F$16,MATCH(A4,Benchmark!$A$2:$A$16,0)) -> 0.58995982 | H4: =C4-G4 -> -0.0040118429 | I4: =_xlfn.MINIFS(Malla!$F$2:$F$234,Malla!$A$2:$A$234,A4) -> 0.12496767
A5: FedYogi | B5: =COUNTIFS(Malla!$A$2:$A$234,A5,Malla!$N$2:$N$234,"ok") -> 36 | C5: =_xlfn.MAXIFS(Malla!$F$2:$F$234,Malla!$A$2:$A$234,A5) -> 0.57920673 | D5: =INDEX(Malla!$B$2:$B$234,MATCH($A5&"|1",Malla!$P$2:$P$234,0)) -> 0.0031622777 | E5: =IF(INDEX(Malla!$C$2:$C$234,MATCH($A5&"|1",Malla!$P$2:$P$234,0))="","",INDEX(Malla!$C$2:$C$234,MATCH($A5&"|1",Malla!$P$2:$P$234,0))) -> 0.0031622777 | F5: =IF(INDEX(Malla!$D$2:$D$234,MATCH($A5&"|1",Malla!$P$2:$P$234,0))="","",INDEX(Malla!$D$2:$D$234,MATCH($A5&"|1",Malla!$P$2:$P$234,0))) | G5: =INDEX(Benchmark!$F$2:$F$16,MATCH(A5,Benchmark!$A$2:$A$16,0)) -> 0.56305463 | H5: =C5-G5 -> 0.016152099 | I5: =_xlfn.MINIFS(Malla!$F$2:$F$234,Malla!$A$2:$A$234,A5) -> 0.125
A6: FedAdagrad | B6: =COUNTIFS(Malla!$A$2:$A$234,A6,Malla!$N$2:$N$234,"ok") -> 43 | C6: =_xlfn.MAXIFS(Malla!$F$2:$F$234,Malla!$A$2:$A$234,A6) -> 0.57455722 | D6: =INDEX(Malla!$B$2:$B$234,MATCH($A6&"|1",Malla!$P$2:$P$234,0)) -> 0.01 | E6: =IF(INDEX(Malla!$C$2:$C$234,MATCH($A6&"|1",Malla!$P$2:$P$234,0))="","",INDEX(Malla!$C$2:$C$234,MATCH($A6&"|1",Malla!$P$2:$P$234,0))) -> 0.01 | F6: =IF(INDEX(Malla!$D$2:$D$234,MATCH($A6&"|1",Malla!$P$2:$P$234,0))="","",INDEX(Malla!$D$2:$D$234,MATCH($A6&"|1",Malla!$P$2:$P$234,0))) | G6: =INDEX(Benchmark!$F$2:$F$16,MATCH(A6,Benchmark!$A$2:$A$16,0)) -> 0.54461635 | H6: =C6-G6 -> 0.029940877 | I6: =_xlfn.MINIFS(Malla!$F$2:$F$234,Malla!$A$2:$A$234,A6) -> 0.098121074
A7: Scaffold | B7: =COUNTIFS(Malla!$A$2:$A$234,A7,Malla!$N$2:$N$234,"ok") -> 46 | C7: =_xlfn.MAXIFS(Malla!$F$2:$F$234,Malla!$A$2:$A$234,A7) -> 0.60926709 | D7: =INDEX(Malla!$B$2:$B$234,MATCH($A7&"|1",Malla!$P$2:$P$234,0)) -> 0.01 | E7: =IF(INDEX(Malla!$C$2:$C$234,MATCH($A7&"|1",Malla!$P$2:$P$234,0))="","",INDEX(Malla!$C$2:$C$234,MATCH($A7&"|1",Malla!$P$2:$P$234,0))) -> 1 | F7: =IF(INDEX(Malla!$D$2:$D$234,MATCH($A7&"|1",Malla!$P$2:$P$234,0))="","",INDEX(Malla!$D$2:$D$234,MATCH($A7&"|1",Malla!$P$2:$P$234,0))) | G7: =INDEX(Benchmark!$F$2:$F$16,MATCH(A7,Benchmark!$A$2:$A$16,0)) -> 0.61572087 | H7: =C7-G7 -> -0.0064537814 | I7: =_xlfn.MINIFS(Malla!$F$2:$F$234,Malla!$A$2:$A$234,A7) -> 0.087543451
A8: Cyclic | B8: =COUNTIFS(Malla!$A$2:$A$234,A8,Malla!$N$2:$N$234,"ok") -> 6 | C8: =_xlfn.MAXIFS(Malla!$F$2:$F$234,Malla!$A$2:$A$234,A8) -> 0.41032058 | D8: =INDEX(Malla!$B$2:$B$234,MATCH($A8&"|1",Malla!$P$2:$P$234,0)) -> 0.01 | E8: =IF(INDEX(Malla!$C$2:$C$234,MATCH($A8&"|1",Malla!$P$2:$P$234,0))="","",INDEX(Malla!$C$2:$C$234,MATCH($A8&"|1",Malla!$P$2:$P$234,0))) | F8: =IF(INDEX(Malla!$D$2:$D$234,MATCH($A8&"|1",Malla!$P$2:$P$234,0))="","",INDEX(Malla!$D$2:$D$234,MATCH($A8&"|1",Malla!$P$2:$P$234,0))) | G8: =INDEX(Benchmark!$F$2:$F$16,MATCH(A8,Benchmark!$A$2:$A$16,0)) -> 0.48350349 | H8: =C8-G8 -> -0.073182902 | I8: =_xlfn.MINIFS(Malla!$F$2:$F$234,Malla!$A$2:$A$234,A8) -> 0.11438894
A9: FedAvgFineTuning | B9: =COUNTIFS(Malla!$A$2:$A$234,A9,Malla!$N$2:$N$234,"ok") -> 5 | C9: =_xlfn.MAXIFS(Malla!$F$2:$F$234,Malla!$A$2:$A$234,A9) -> 0.61770437 | D9: =INDEX(Malla!$B$2:$B$234,MATCH($A9&"|1",Malla!$P$2:$P$234,0)) -> 0.01 | E9: =IF(INDEX(Malla!$C$2:$C$234,MATCH($A9&"|1",Malla!$P$2:$P$234,0))="","",INDEX(Malla!$C$2:$C$234,MATCH($A9&"|1",Malla!$P$2:$P$234,0))) | F9: =IF(INDEX(Malla!$D$2:$D$234,MATCH($A9&"|1",Malla!$P$2:$P$234,0))="","",INDEX(Malla!$D$2:$D$234,MATCH($A9&"|1",Malla!$P$2:$P$234,0))) | G9: =INDEX(Benchmark!$F$2:$F$16,MATCH(A9,Benchmark!$A$2:$A$16,0)) -> 0.61392588 | H9: =C9-G9 -> 0.003778491 | I9: =_xlfn.MINIFS(Malla!$F$2:$F$234,Malla!$A$2:$A$234,A9) -> 0.321248
A11: Si dos corridas empatan en el máximo, lr/slr/mu muestran la primera.

Sheet Best config
A1: Estrategia / Método | B1: lr cliente | C1: lr servidor (slr) | D1: mu (FedProx) | E1: pasos fine-tuning | F1: Pooled test | G1: BCN | H1: HAM_vidir_molemax | I1: HAM_vidir_modern | J1: HAM_rosendahl | K1: MSK | L1: HAM_vienna_dias | M1: Media 6 centros
A2: FedAvg | B2: 0.01 | F2: 0.59042224 | G2: 0.63169449 | H2: 0.60070179 | I2: 0.665932 | J2: 0.47664909 | K2: 0.38816739 | L2: 0.70364114 | M2: =IF(COUNT(G2:L2)=6,AVERAGE(G2:L2),"") -> 0.57779765
A3: FedProx | B3: 0.01 | D3: 0.001 | F3: 0.61602263 | G3: 0.64523574 | H3: 0.68467602 | I3: 0.58701778 | J3: 0.53899947 | K3: 0.44238301 | L3: 0.71715465 | M3: =IF(COUNT(G3:L3)=6,AVERAGE(G3:L3),"") -> 0.60257778
A4: FedAdam | B4: 0.01 | C4: 0.0031622777 | F4: 0.5898459 | G4: 0.60651602 | H4: 0.72902326 | I4: 0.71758576 | J4: 0.53805612 | K4: 0.36775922 | L4: 0.65409159 | M4: =IF(COUNT(G4:L4)=6,AVERAGE(G4:L4),"") -> 0.602172
A5: FedYogi | B5: 0.01 | C5: 0.0031622777 | F5: 0.56868784 | G5: 0.59196846 | H5: 0.74842338 | I5: 0.69653303 | J5: 0.44655298 | K5: 0.38641517 | L5: 0.72391141 | M5: =IF(COUNT(G5:L5)=6,AVERAGE(G5:L5),"") -> 0.59896741
A6: FedAdagrad | B6: 0.01 | C6: 0.031622777 | F6: 0.54657124 | G6: 0.59221528 | H6: 0.66660258 | I6: 0.52717387 | J6: 0.37990949 | K6: 0.36446094 | L6: 0.82526276 | M6: =IF(COUNT(G6:L6)=6,AVERAGE(G6:L6),"") -> 0.55927082
A7: Scaffold | B7: 0.01 | C7: 1 | F7: 0.6236299 | G7: 0.66644895 | H7: 0.64866372 | I7: 0.72429493 | J7: 0.50237318 | K7: 0.3178726 | L7: 0.65878378 | M7: =IF(COUNT(G7:L7)=6,AVERAGE(G7:L7),"") -> 0.5864062
A8: Cyclic | B8: 0.0031622777 | F8: 0.44358641 | G8: 0.48400277 | H8: 0.42124057 | I8: 0.58795076 | J8: 0.37881423 | K8: 0.23778602 | L8: 0.59309309 | M8: =IF(COUNT(G8:L8)=6,AVERAGE(G8:L8),"") -> 0.45048124
A9: FedAvgFineTuning | B9: 0.01 | E9: 3 | F9: 0.65046081 | G9: 0.69015278 | H9: 0.67057297 | I9: 0.72981616 | J9: 0.51771341 | K9: 0.41774892 | L9: 0.72297297 | M9: =IF(COUNT(G9:L9)=6,AVERAGE(G9:L9),"") -> 0.62482954

Sheet Benchmark rerun
A1: Estrategia / Método | B1: lr cliente | C1: lr servidor (slr) | D1: mu (FedProx) | E1: pasos fine-tuning | F1: Pooled test | G1: BCN | H1: HAM_vidir_molemax | I1: HAM_vidir_modern | J1: HAM_rosendahl | K1: MSK | L1: HAM_vienna_dias | M1: Media 6 centros
A2: FedAvg | B2: 0.01 | F2: 0.57131871 | G2: 0.60100509 | H2: 0.64018458 | I2: 0.53084788 | J2: 0.44302928 | K2: 0.42393321 | L2: 0.82526276 | M2: =IF(COUNT(G2:L2)=6,AVERAGE(G2:L2),"") -> 0.57737713
A3: FedProx | B3: 0.01 | D3: 0.001 | F3: 0.61546771 | G3: 0.6501431 | H3: 0.68761777 | I3: 0.57078416 | J3: 0.47768717 | K3: 0.43733251 | L3: 0.6859985 | M3: =IF(COUNT(G3:L3)=6,AVERAGE(G3:L3),"") -> 0.5849272
A4: FedAdam | B4: 0.01 | C4: 0.0031622777 | F4: 0.58349765 | G4: 0.60283226 | H4: 0.67026533 | I4: 0.69703416 | J4: 0.48307226 | K4: 0.44939188 | L4: 0.67999249 | M4: =IF(COUNT(G4:L4)=6,AVERAGE(G4:L4),"") -> 0.59709806
A5: FedYogi | B5: 0.01 | C5: 0.0031622777 | F5: 0.59316279 | G5: 0.61693773 | H5: 0.6730821 | I5: 0.72209168 | J5: 0.51520752 | K5: 0.37981859 | L5: 0.6753003 | M5: =IF(COUNT(G5:L5)=6,AVERAGE(G5:L5),"") -> 0.59707299
A6: FedAdagrad | B6: 0.01 | C6: 0.031622777 | F6: 0.56552291 | G6: 0.59804064 | H6: 0.67859066 | I6: 0.56691981 | J6: 0.41214318 | K6: 0.45949289 | L6: 0.75525526 | M6: =IF(COUNT(G6:L6)=6,AVERAGE(G6:L6),"") -> 0.57840707
A7: Scaffold | B7: 0.01 | C7: 1 | F7: 0.59908646 | G7: 0.62755688 | H7: 0.61955393 | I7: 0.6978902 | J7: 0.50001786 | K7: 0.35384457 | L7: 0.62331081 | M7: =IF(COUNT(G7:L7)=6,AVERAGE(G7:L7),"") -> 0.57036238
A8: FedAvgFineTuning | B8: 0.01 | E8: 3 | F8: 0.61170435 | G8: 0.63947167 | H8: 0.75219189 | I8: 0.68042117 | J8: 0.51829648 | K8: 0.4004329 | L8: 0.71959459 | M8: =IF(COUNT(G8:L8)=6,AVERAGE(G8:L8),"") -> 0.61840145

Sheet Repeticiones
A1: Estrategia | B1: Benchmark | C1: Rerun | D1: Best config | E1: N corridas | F1: Media | G1: Desv. estándar | H1: Rango (máx − mín)
A2: FedAvg | B2: =IFERROR(INDEX(Benchmark!$F$2:$F$16,MATCH($A2,Benchmark!$A$2:$A$16,0)),"") -> 0.57804038 | C2: =IFERROR(INDEX('Benchmark rerun'!$F$2:$F$8,MATCH($A2,'Benchmark rerun'!$A$2:$A$8,0)),"") -> 0.57131871 | D2: =IFERROR(INDEX('Best config'!$F$2:$F$9,MATCH($A2,'Best config'!$A$2:$A$9,0)),"") -> 0.59042224 | E2: =COUNT(B2:D2) -> 3 | F2: =AVERAGE(B2:D2) -> 0.57992711 | G2: =IF(E2>1,STDEV(B2:D2),"") -> 0.0096905105 | H2: =MAX(B2:D2)-MIN(B2:D2) -> 0.019103526
A3: FedProx | B3: =IFERROR(INDEX(Benchmark!$F$2:$F$16,MATCH($A3,Benchmark!$A$2:$A$16,0)),"") -> 0.58924231 | C3: =IFERROR(INDEX('Benchmark rerun'!$F$2:$F$8,MATCH($A3,'Benchmark rerun'!$A$2:$A$8,0)),"") -> 0.61546771 | D3: =IFERROR(INDEX('Best config'!$F$2:$F$9,MATCH($A3,'Best config'!$A$2:$A$9,0)),"") -> 0.61602263 | E3: =COUNT(B3:D3) -> 3 | F3: =AVERAGE(B3:D3) -> 0.60691088 | G3: =IF(E3>1,STDEV(B3:D3),"") -> 0.015303948 | H3: =MAX(B3:D3)-MIN(B3:D3) -> 0.02678032
A4: FedAdam | B4: =IFERROR(INDEX(Benchmark!$F$2:$F$16,MATCH($A4,Benchmark!$A$2:$A$16,0)),"") -> 0.58995982 | C4: =IFERROR(INDEX('Benchmark rerun'!$F$2:$F$8,MATCH($A4,'Benchmark rerun'!$A$2:$A$8,0)),"") -> 0.58349765 | D4: =IFERROR(INDEX('Best config'!$F$2:$F$9,MATCH($A4,'Best config'!$A$2:$A$9,0)),"") -> 0.5898459 | E4: =COUNT(B4:D4) -> 3 | F4: =AVERAGE(B4:D4) -> 0.58776779 | G4: =IF(E4>1,STDEV(B4:D4),"") -> 0.0036984899 | H4: =MAX(B4:D4)-MIN(B4:D4) -> 0.0064621771
A5: FedYogi | B5: =IFERROR(INDEX(Benchmark!$F$2:$F$16,MATCH($A5,Benchmark!$A$2:$A$16,0)),"") -> 0.56305463 | C5: =IFERROR(INDEX('Benchmark rerun'!$F$2:$F$8,MATCH($A5,'Benchmark rerun'!$A$2:$A$8,0)),"") -> 0.59316279 | D5: =IFERROR(INDEX('Best config'!$F$2:$F$9,MATCH($A5,'Best config'!$A$2:$A$9,0)),"") -> 0.56868784 | E5: =COUNT(B5:D5) -> 3 | F5: =AVERAGE(B5:D5) -> 0.57496842 | G5: =IF(E5>1,STDEV(B5:D5),"") -> 0.016006549 | H5: =MAX(B5:D5)-MIN(B5:D5) -> 0.030108161
A6: FedAdagrad | B6: =IFERROR(INDEX(Benchmark!$F$2:$F$16,MATCH($A6,Benchmark!$A$2:$A$16,0)),"") -> 0.54461635 | C6: =IFERROR(INDEX('Benchmark rerun'!$F$2:$F$8,MATCH($A6,'Benchmark rerun'!$A$2:$A$8,0)),"") -> 0.56552291 | D6: =IFERROR(INDEX('Best config'!$F$2:$F$9,MATCH($A6,'Best config'!$A$2:$A$9,0)),"") -> 0.54657124 | E6: =COUNT(B6:D6) -> 3 | F6: =AVERAGE(B6:D6) -> 0.55223683 | G6: =IF(E6>1,STDEV(B6:D6),"") -> 0.011547521 | H6: =MAX(B6:D6)-MIN(B6:D6) -> 0.020906559
A7: Scaffold | B7: =IFERROR(INDEX(Benchmark!$F$2:$F$16,MATCH($A7,Benchmark!$A$2:$A$16,0)),"") -> 0.61572087 | C7: =IFERROR(INDEX('Benchmark rerun'!$F$2:$F$8,MATCH($A7,'Benchmark rerun'!$A$2:$A$8,0)),"") -> 0.59908646 | D7: =IFERROR(INDEX('Best config'!$F$2:$F$9,MATCH($A7,'Best config'!$A$2:$A$9,0)),"") -> 0.6236299 | E7: =COUNT(B7:D7) -> 3 | F7: =AVERAGE(B7:D7) -> 0.61281241 | G7: =IF(E7>1,STDEV(B7:D7),"") -> 0.012527545 | H7: =MAX(B7:D7)-MIN(B7:D7) -> 0.024543432
A8: Cyclic | B8: =IFERROR(INDEX(Benchmark!$F$2:$F$16,MATCH($A8,Benchmark!$A$2:$A$16,0)),"") -> 0.48350349 | C8: =IFERROR(INDEX('Benchmark rerun'!$F$2:$F$8,MATCH($A8,'Benchmark rerun'!$A$2:$A$8,0)),"") | D8: =IFERROR(INDEX('Best config'!$F$2:$F$9,MATCH($A8,'Best config'!$A$2:$A$9,0)),"") -> 0.44358641 | E8: =COUNT(B8:D8) -> 2 | F8: =AVERAGE(B8:D8) -> 0.46354495 | G8: =IF(E8>1,STDEV(B8:D8),"") -> 0.028225638 | H8: =MAX(B8:D8)-MIN(B8:D8) -> 0.03991708
A9: FedAvgFineTuning | B9: =IFERROR(INDEX(Benchmark!$F$2:$F$16,MATCH($A9,Benchmark!$A$2:$A$16,0)),"") -> 0.61392588 | C9: =IFERROR(INDEX('Benchmark rerun'!$F$2:$F$8,MATCH($A9,'Benchmark rerun'!$A$2:$A$8,0)),"") -> 0.61170435 | D9: =IFERROR(INDEX('Best config'!$F$2:$F$9,MATCH($A9,'Best config'!$A$2:$A$9,0)),"") -> 0.65046081 | E9: =COUNT(B9:D9) -> 3 | F9: =AVERAGE(B9:D9) -> 0.62536368 | G9: =IF(E9>1,STDEV(B9:D9),"") -> 0.021763119 | H9: =MAX(B9:D9)-MIN(B9:D9) -> 0.038756461
A11: Pooled test, misma config (config_isic2019.json) y semilla 42 en la misma máquina. Cyclic no tiene rerun.

Sheet FLamby paper
A1: Método | B1: Seed 42 | C1: Seed 43 | D1: Seed 44 | E1: Seed 45 | F1: Seed 46 | G1: Media FLamby | H1: Desv. FLamby | I1: Nuestro (seed 42) | J1: Nuestro − media | K1: ¿Dentro de ±2 desv.?
A2: Pooled Training | B2: 0.75550347 | C2: 0.77586004 | D2: 0.75810952 | E2: 0.76992133 | F2: 0.75162119 | G2: =AVERAGE(B2:F2) -> 0.76220311 | H2: =STDEV(B2:F2) -> 0.010243317 | I2: =IFERROR(INDEX(Benchmark!$F$2:$F$16,MATCH(A2,Benchmark!$A$2:$A$16,0)),"") -> 0.74981289 | J2: =IF(I2="","",I2-G2) -> -0.012390218 | K2: =IF(I2="","",IF(ABS(J2)<=2*H2,"sí","no")) -> sí
A3: Local 0 | B3: 0.66953172 | C3: 0.66313956 | D3: 0.65735906 | E3: 0.67664672 | F3: 0.65426405 | G3: =AVERAGE(B3:F3) -> 0.66418822 | H3: =STDEV(B3:F3) -> 0.0090828614 | I3: =IFERROR(INDEX(Benchmark!$F$2:$F$16,MATCH(A3,Benchmark!$A$2:$A$16,0)),"") -> 0.65823531 | J3: =IF(I3="","",I3-G3) -> -0.0059529075 | K3: =IF(I3="","",IF(ABS(J3)<=2*H3,"sí","no")) -> sí
A4: Local 1 | B4: 0.28873079 | C4: 0.27246718 | D4: 0.29578619 | E4: 0.27275157 | F4: 0.30369677 | G4: =AVERAGE(B4:F4) -> 0.2866865 | H4: =STDEV(B4:F4) -> 0.013898775 | I4: =IFERROR(INDEX(Benchmark!$F$2:$F$16,MATCH(A4,Benchmark!$A$2:$A$16,0)),"") -> 0.27797721 | J4: =IF(I4="","",I4-G4) -> -0.0087092915 | K4: =IF(I4="","",IF(ABS(J4)<=2*H4,"sí","no")) -> sí
A5: Local 2 | B5: 0.44063332 | C5: 0.42470493 | D5: 0.43326145 | E5: 0.41732709 | F5: 0.44293487 | G5: =AVERAGE(B5:F5) -> 0.43177233 | H5: =STDEV(B5:F5) -> 0.01076975 | I5: =IFERROR(INDEX(Benchmark!$F$2:$F$16,MATCH(A5,Benchmark!$A$2:$A$16,0)),"") -> 0.44946632 | J5: =IF(I5="","",I5-G5) -> 0.017693994 | K5: =IF(I5="","",IF(ABS(J5)<=2*H5,"sí","no")) -> sí
A6: Local 3 | B6: 0.32892355 | C6: 0.33340585 | D6: 0.38387492 | E6: 0.35064035 | F6: 0.35149456 | G6: =AVERAGE(B6:F6) -> 0.34966785 | H6: =STDEV(B6:F6) -> 0.021617032 | I6: =IFERROR(INDEX(Benchmark!$F$2:$F$16,MATCH(A6,Benchmark!$A$2:$A$16,0)),"") -> 0.35036771 | J6: =IF(I6="","",I6-G6) -> 0.00069986443 | K6: =IF(I6="","",IF(ABS(J6)<=2*H6,"sí","no")) -> sí
A7: Local 4 | B7: 0.18163916 | C7: 0.18461685 | D7: 0.1778387 | E7: 0.18606992 | F7: 0.18654653 | G7: =AVERAGE(B7:F7) -> 0.18334223 | H7: =STDEV(B7:F7) -> 0.0036235971 | I7: =IFERROR(INDEX(Benchmark!$F$2:$F$16,MATCH(A7,Benchmark!$A$2:$A$16,0)),"") -> 0.19042508 | J7: =IF(I7="","",I7-G7) -> 0.0070828515 | K7: =IF(I7="","",IF(ABS(J7)<=2*H7,"sí","no")) -> sí
A8: Local 5 | B8: 0.15310174 | C8: 0.13826802 | D8: 0.1515047 | E8: 0.13212835 | F8: 0.1449392 | G8: =AVERAGE(B8:F8) -> 0.1439884 | H8: =STDEV(B8:F8) -> 0.0088576984 | I8: =IFERROR(INDEX(Benchmark!$F$2:$F$16,MATCH(A8,Benchmark!$A$2:$A$16,0)),"") -> 0.14133758 | J8: =IF(I8="","",I8-G8) -> -0.0026508204 | K8: =IF(I8="","",IF(ABS(J8)<=2*H8,"sí","no")) -> sí
A9: FedAvg | B9: 0.58061849 | C9: 0.57387262 | D9: 0.59105057 | E9: 0.59340655 | F9: 0.33046837 | G9: =AVERAGE(B9:F9) -> 0.53388332 | H9: =STDEV(B9:F9) -> 0.11398692 | I9: =IFERROR(INDEX(Benchmark!$F$2:$F$16,MATCH(A9,Benchmark!$A$2:$A$16,0)),"") -> 0.57804038 | J9: =IF(I9="","",I9-G9) -> 0.044157062 | K9: =IF(I9="","",IF(ABS(J9)<=2*H9,"sí","no")) -> sí
A10: FedProx | B10: 0.55023928 | C10: 0.59913013 | D10: 0.52136466 | E10: 0.60566728 | F10: 0.44463803 | G10: =AVERAGE(B10:F10) -> 0.54420788 | H10: =STDEV(B10:F10) -> 0.065700183 | I10: =IFERROR(INDEX(Benchmark!$F$2:$F$16,MATCH(A10,Benchmark!$A$2:$A$16,0)),"") -> 0.58924231 | J10: =IF(I10="","",I10-G10) -> 0.045034432 | K10: =IF(I10="","",IF(ABS(J10)<=2*H10,"sí","no")) -> sí
A11: FedAdam | B11: 0.58439327 | C11: 0.57915117 | D11: 0.5706 | E11: 0.5619483 | F11: 0.58041847 | G11: =AVERAGE(B11:F11) -> 0.57530224 | H11: =STDEV(B11:F11) -> 0.0090010549 | I11: =IFERROR(INDEX(Benchmark!$F$2:$F$16,MATCH(A11,Benchmark!$A$2:$A$16,0)),"") -> 0.58995982 | J11: =IF(I11="","",I11-G11) -> 0.014657582 | K11: =IF(I11="","",IF(ABS(J11)<=2*H11,"sí","no")) -> sí
A12: FedYogi | B12: 0.51018767 | C12: 0.5642641 | D12: 0.55132823 | E12: 0.57049132 | F12: 0.52505457 | G12: =AVERAGE(B12:F12) -> 0.54426518 | H12: =STDEV(B12:F12) -> 0.02582624 | I12: =IFERROR(INDEX(Benchmark!$F$2:$F$16,MATCH(A12,Benchmark!$A$2:$A$16,0)),"") -> 0.56305463 | J12: =IF(I12="","",I12-G12) -> 0.018789455 | K12: =IF(I12="","",IF(ABS(J12)<=2*H12,"sí","no")) -> sí
A13: FedAdagrad | B13: 0.52878335 | C13: 0.53184396 | D13: 0.53542385 | E13: 0.59973586 | F13: 0.53410615 | G13: =AVERAGE(B13:F13) -> 0.54597863 | H13: =STDEV(B13:F13) -> 0.030156531 | I13: =IFERROR(INDEX(Benchmark!$F$2:$F$16,MATCH(A13,Benchmark!$A$2:$A$16,0)),"") -> 0.54461635 | J13: =IF(I13="","",I13-G13) -> -0.0013622876 | K13: =IF(I13="","",IF(ABS(J13)<=2*H13,"sí","no")) -> sí
... A15: Cyclic | B15: 0.45922871 | C15: 0.44543137 | D15: 0.43323498 | E15: 0.39537795 | F15: 0.39721885 | G15: =AVERAGE(B15:F15) -> 0.42609837 | H15: =STDEV(B15:F15) -> 0.02872319 | I15: =IFERROR(INDEX(Benchmark!$F$2:$F$16,MATCH(A15,Benchmark!$A$2:$A$16,0)),"") -> 0.48350349 | J15: =IF(I15="","",I15-G15) -> 0.057405114 | K15: =IF(I15="","",IF(ABS(J15)<=2*H15,"sí","no")) -> sí
A17: Seeds 42–46 (azul): pooled test publicado por FLamby en flamby/results/results_benchmark_fed_isic2019/isic_seed<S>.csv. FedAvgFineTuning no está en sus resultados.

Sheet Métricas detalladas
A1: Origen | B1: Carpeta de la corrida | C1: balanced_accuracy | D1: accuracy | E1: auc | F1: f1 | G1: f1_macro | H1: precision | I1: sensitivity | J1: specificity | K1: loss
A2: runs | B2: pooled | C2: 0.74981289 | D2: 0.78989247 | E2: 0.96413715 | F2: 0.79267563 | G2: 0.71856907 | H2: 0.69827492 | I2: 0.74981289 | J2: 0.96585522 | K2: 4.3313044
A3: runs | B3: FedAvg-num-updates100-lr0.001 | C3: 0.51332405 | D3: 0.56215054 | E3: 0.87171713 | F3: 0.58198635 | G3: 0.4026974 | H3: 0.38567365 | I3: 0.51332405 | J3: 0.93095766 | K3: 6.8104999
A4: runs | B4: FedAvg-num-updates100-lr0.0031622776601683 | C4: 0.58331566 | D4: 0.62666667 | E4: 0.90343644 | F4: 0.63660422 | G4: 0.50195257 | H4: 0.47791361 | I4: 0.58331566 | J4: 0.93971841 | K4: 5.7502309
A5: runs | B5: FedAvg-num-updates100-lr0.01 | C5: 0.59249776 | D5: 0.67182796 | E5: 0.92374557 | F5: 0.67045151 | G5: 0.54940202 | H5: 0.5486996 | I5: 0.59249776 | J5: 0.9433481 | K5: 5.6163558
A6: runs | B6: FedAvg-num-updates100-lr0.0316227766016837 | C6: 0.57499028 | D6: 0.57139785 | E6: 0.88525534 | F6: 0.59217268 | G6: 0.43864209 | H6: 0.40650277 | I6: 0.57499028 | J6: 0.93307364 | K6: 6.2100488
A7: runs | B7: FedAvg-num-updates100-lr0.1 | C7: 0.2474994 | D7: 0.37870968 | E7: 0.77732088 | F7: 0.38225448 | G7: 0.20482596 | H7: 0.36533902 | I7: 0.2474994 | J7: 0.90487158 | K7: 13.780469
A8: runs | B8: FedAvg-num-updates100-lr0.316227766016838 | C8: 0.2285311 | D8: 0.30537634 | E8: 0.70241059 | F8: 0.33500005 | G8: 0.13329682 | H8: 0.16140005 | I8: 0.2285311 | J8: 0.89845341 | K8: 12.263282
A9: runs | B9: FedProx-num-updates100-lr0.001-mu0.001 | C9: 0.51375008 | D9: 0.56430108 | E9: 0.86852425 | F9: 0.58234582 | G9: 0.40166003 | H9: 0.38483583 | I9: 0.51375008 | J9: 0.93085405 | K9: 6.9391695
A10: runs | B10: FedProx-num-updates100-lr0.001-mu0.01 | C10: 0.50979786 | D10: 0.56107527 | E10: 0.87047913 | F10: 0.58086605 | G10: 0.39858899 | H10: 0.38200246 | I10: 0.50979786 | J10: 0.93062421 | K10: 6.8297034
A11: runs | B11: FedProx-num-updates100-lr0.001-mu0.1 | C11: 0.51298224 | D11: 0.56451613 | E11: 0.87071569 | F11: 0.58430586 | G11: 0.40285696 | H11: 0.38640403 | I11: 0.51298224 | J11: 0.93115162 | K11: 6.864228
A12: runs | B12: FedProx-num-updates100-lr0.001-mu1.0 | C12: 0.50790298 | D12: 0.55698925 | E12: 0.86815158 | F12: 0.57765175 | G12: 0.3953823 | H12: 0.37801477 | I12: 0.50790298 | J12: 0.93041543 | K12: 6.9058055
A13: runs | B13: FedProx-num-updates100-lr0.0031622776601683-mu0.001 | C13: 0.57338443 | D13: 0.62731183 | E13: 0.90155856 | F13: 0.63436453 | G13: 0.48228121 | H13: 0.45375557 | I13: 0.57338443 | J13: 0.93854652 | K13: 5.8142949
... A217: runs_best | B217: FedAvgFineTuning-num-updates100-lr0.01 | C217: 0.65046081 | D217: 0.59913978 | E217: 0.91783936 | F217: 0.61739409 | G217: 0.54222899 | H217: 0.51039568 | I217: 0.65046081 | J217: 0.93819458 | K217: 4.9433642
